Workbook

Sheet DATOS
B3: EJERCICIO INTEGRAL DE COSTOS POR ÓRDENES DE PRODUCCION
B5: La empresa industria de producción textil de camisetas “ALAN SPORT” fabrica camisetas polo para hombre de las tallas S,M,L. Trabaja bajo un sistema de costos por órdenes de producción.
B8: PRODUCTO | C8: TELA | D8: CUELLO | E8: PUÑOS | F8: BOTON | G8: HILO
B9: Camiseta S | C9: 80 cm | D9: 1 | E9: 2 | F9: 2 | G9: 4mt
B10: Camiseta M | C10: 90 cm | D10: 1 | E10: 2 | F10: 2 | G10: 5mt
B11: Camiseta L | C11: 1,10 cm | D11: 1 | E11: 2 | F11: 2 | G11: 6mt | H11: 15 | I11: DIARIO | J11: 3 DIAS
B12: PRECIO U. | C12: 4.2 | D12: 0.5 | E12: 0.2 | F12: 0.05 | G12: 3 | H12: =C24*H11 -> 150000 | I12: =H12/5 -> 30000 | J12: =I12*3 -> 90000
B14: Sus datos iniciales de inventario son
B15: PRODUCTO | C15: TELA | D15: CUELLO | E15: PUÑOS | F15: BOTON | G15: HILO
C16: 100 rollos 45mt | D16: 3000 | E16: 5000 | F16: 40000 | G16: 100 Conos
B19: En una semana de producción se produce
B20: PRODUCTO | C20: CANTIDAD
B21: Camiseta S | C21: 3000 | D21: =C21*80 -> 240000
B22: Camiseta M | C22: 3700 | D22: =C22*90 -> 333000
B23: Camiseta L | C23: 3300 | D23: =C23*110 -> 363000
C24: 10000 | D24: =SUM(D21:D23) -> 936000 | F24: STOCK
C25: METROS: | D25: =D24/100 -> 9360 | E25: =D25/5 -> 1872 | F25: =E25*3 -> 5616
B28: Además, tiene en el banco $ 80.000, en maquinaria $70.000,00, debe a proveedores $15000 y en sus ventas se margina una utilidad del 80%, la empresa cuenta con los siguientes trabajadores:
B29: 30 obreros con un sueldo básico de $482, el 50% de ellos trabajan más de un año, horas extras frecuentes de 4 normales y 8 extraordinarias, se considera que el 25% del tiempo se destina a fabricar la talla S, el 40% la M y el 35% la L.
B32: 1 jefe de producción y 1 supervisor con un sueldo de $ 700 y $ 650 respectivamente, todos trabajan más de un año, bonos de producción frecuentes de $ 60 y $ 100 respectivamente. Sus pagos son semanalmente.
B35: En lo referente a los costos indirectos de fabricación la empresa determina su aplicación en base a unidades producidas y que como costos indirectos mensuales tenemos energía eléctrica $500, mantenimiento $25 por máquina, seguros de fabrica $350 y la correspondiente depreciación.
B39: Las órdenes de producción durante el mes de enero del 2026 fueron las siguientes:
B41: Enero 05: se recibe un pedido por parte TOMY para una producción de
B43: PRODUCTO | C43: CANTIDAD
B44: Camiseta S | C44: 4000
B45: Camiseta M | C45: 6000
B46: Camiseta L | C46: 5000 | D46: =C44+C45+C46 -> 15000
B48: La fecha estimada de entrega es el
B49: ENERO : se recibe un pedido de TEXPAX para la fabricación de
B51: PRODUCTO | C51: CANTIDAD
B52: Camiseta S | C52: 5000
B53: Camiseta M | C53: 6000
B54: Camiseta L | C54: 9000
D55: =C52+C53+C54 -> 20000
B56: La fecha estimada de entrega es el
B57: Para la fabricación y venta se asume que la empresa compra lo necesario para su producción con un incremento del 10%, y vende sus productos en las fechas terminadas con el 80% de ganancia.
B60: Comprar materia prima y mandar a produccion, 2, 3

Sheet LIBRO DIARIO
B2: INDUSTRIAS "ALAN SPORT"
B3: LIBRO DIARIO
F5: FOLIO: | G5: 1
B6: FECHA | C6: DETALLE | D6: N/M | E6: PARCIAL | F6: DEBE | G6: HABER
B7: 46027 | C7: --------------------------- 1 ---------------------------
C8: BANCOS | D8: 1 | F8: 80000
C9: INV. MATERIA PRIMA DIRECTA | D9: 2 | F9: =KARDEX!L9+KARDEX!L25+KARDEX!L41+KARDEX!L57 -> 23400
C10: INV. MATERIA PRIMA INDIRECTA | D10: 3 | F10: =KARDEX!L73 -> 300
C11: MAQUINARIA | D11: 4 | F11: 70000
C12: PROVEEDORES | D12: 5 | G12: 15000
C13: CAPITAL | D13: 6 | G13: =(F8+F9+F10+F11)-G12 -> 158700
C14: P/R la situació inicial de la industria
B15: 46027 | C15: --------------------------- 2 ---------------------------
C16: INV. MATERIA PRIMA DIRECTA | D16: 2 | F16: =KARDEX!F10+KARDEX!F26+KARDEX!F42+KARDEX!F58 -> 88447.92
C17: INV. MATERIA PRIMA DIRECTA | D17: 3 | F17: =KARDEX!F75 -> 0
C18: PROVEEDORES | D18: 5 | G18: =F16+F17 -> 88447.92
C19: P/R la compra de materia prima para la OP#100 a crédito
B20: 46027 | C20: --------------------------- 3 ---------------------------
C21: PRODUCCIÓN PROCESO OP#100 TS | D21: 7 | F21: =KARDEX!I11+KARDEX!I27+KARDEX!I43+KARDEX!I59+KARDEX!I75 -> 18807.53
C22: PRODUCCIÓN PROCESO OP#100 TM | D22: 8 | F22: =KARDEX!I12+KARDEX!I28+KARDEX!I44+KARDEX!I60+KARDEX!I76 -> 30931.778
C23: PRODUCCIÓN PROCESO OP#100 TL | D23: 9 | F23: =KARDEX!I13+KARDEX!I29+KARDEX!I45+KARDEX!I61+KARDEX!I77 -> 30305.62
C24: INV. MATERIA PRIMA DIRECTA | D24: 2 | G24: =KARDEX!I11+KARDEX!I12+KARDEX!I13+KARDEX!I27+KARDEX!I28+KARDEX!I30+KARDEX!I43+KARDEX!I44+KARDEX!I45+KARDEX!I59+KARDEX!I60+KARDEX!I61 -> 77254.642
C25: INV. MATERIA PRIMA INDIRECTA | D25: 3 | G25: =KARDEX!I75+KARDEX!I76+KARDEX!I77 -> 76
C26: P/R el envio de materia prima directa e indirecta para la OP#100
B27: 46031 | C27: --------------------------- 4 ---------------------------
C28: MANO DE OBRA DIRECTA | D28: 10 | F28: =('ROL MOD'!G35+'ROL MOD'!H35+'ROL MOD'!I35+'ROL MOD'!J35+'ROL MOD'!K35+'ROL MOD'!L35+'ROL MOD'!F77+'ROL MOD'!G77+'ROL MOD'!H77+'ROL MOD'!I77+'ROL MOD'!J77)/4 -> 5598.2718
C29: MANO DE OBRA INDIRECTA | D29: 11 | F29: =('ROL MOD'!G41+'ROL MOD'!H41+'ROL MOD'!I41+'ROL MOD'!J41+'ROL MOD'!K41+'ROL MOD'!L41+'ROL MOD'!F83+'ROL MOD'!G83+'ROL MOD'!H83+'ROL MOD'!I83+'ROL MOD'!J83)/4 -> 583.80799
C30: IESS POR PAGAR | D30: 12 | G30: =('ROL MOD'!N35+'ROL MOD'!N41+'ROL MOD'!J77+'ROL MOD'!J83)/4 -> 979.76925
C31: XIII SUELDO POR PAGAR | D31: 13 | G31: =('ROL MOD'!F77+'ROL MOD'!F83)/4 -> 377.9974
C32: XIV SUELDO POR PAGAR | D32: 14 | G32: =('ROL MOD'!G77+'ROL MOD'!G83)/4 -> 321.33333
C33: VACACIONES | D33: 15 | G33: =('ROL MOD'!H77+'ROL MOD'!H83)/4 -> 188.9987
C34: BANCOS | D34: 1 | G34: =('ROL MOD'!S35+'ROL MOD'!S41)/4 -> 4313.9812
C35: P/R el pago de la mod y moi de una semana de la op#100
B36: =B27 -> 46031 | C36: --------------------------- 5 ---------------------------
C37: PRODUCCIÓN PROCESO OP#100 TS | D37: 7 | F37: =(G40*25%)+(G41*25%) -> 1545.52
C38: PRODUCCIÓN PROCESO OP#100 TM | D38: 8 | F38: =(G40*40%)+(G41*40%) -> 2472.8319
C39: PRODUCCIÓN PROCESO OP#100 TL | D39: 9 | F39: =(G40*35%)+(G41*35%) -> 2163.7279
C40: MANO DE OBRA DIRECTA | G40: =F28 -> 5598.2718
C41: MANO DE OBRA INDIRECTA | G41: =F29 -> 583.80799
C42: P/R el cargo de la mod y moi para OP#100
...

Sheet MAYORIZACIÓN
B3: Industrias "ALAN SPORT" | J3: Industrias "ALAN SPORT"
B4: LIBRO MAYOR | J4: LIBRO MAYOR
B5: CUENTA | C5: ='LIBRO DIARIO'!C8 -> BANCOS | G5: No | H5: 1 | J5: CUENTA | K5: ='LIBRO DIARIO'!C9 -> INV. MATERIA PRIMA DIRECTA | O5: No | P5: 2
B6: FECHA | C6: DETALLE | D6: F | E6: A | F6: DEBE | G6: HABER | H6: SALDO | J6: FECHA | K6: DETALLE | L6: F | M6: A | N6: DEBE | O6: HABER | P6: SALDO
B7: ='LIBRO DIARIO'!B7 -> 46027 | C7: A VARIOS | D7: 1 | E7: 1 | F7: ='LIBRO DIARIO'!F8 -> 80000 | H7: =F7-G7 -> 80000 | J7: ='LIBRO DIARIO'!B7 -> 46027 | K7: A VARIOS | L7: 1 | M7: 1 | N7: ='LIBRO DIARIO'!F9 -> 23400 | P7: =N7-O7 -> 23400
B8: ='LIBRO DIARIO'!B27 -> 46031 | C8: POR MOD Y MOI | D8: 1 | E8: 4 | G8: ='LIBRO DIARIO'!G34 -> 4313.9812 | H8: =(H7+F8)-G8 -> 75686.019 | J8: ='LIBRO DIARIO'!B15 -> 46027 | K8: A PROVEEDORES | L8: 1 | M8: 2 | N8: ='LIBRO DIARIO'!F16 -> 88447.92 | P8: =(P7+N8)-O8 -> 111847.92
B9: ='[1]LIBRO DIARIO'!B26 -> 46030 | C9: A VENTAS | D9: 1 | E9: 5 | F9: ='[1]LIBRO DIARIO'!F27 -> 83661.111 | H9: =(H8+F9)-G9 -> 159347.13 | J9: ='LIBRO DIARIO'!B20 -> 46027 | K9: POR PRODUCCIÓN.PROCESO | L9: 1 | M9: 3 | O9: ='LIBRO DIARIO'!G24 -> 77254.642 | P9: =(P8+N9)-O9 -> 34593.278 | Q9: 79698.93
B10: ='[1]LIBRO DIARIO'!B26 -> 46030 | C10: POR BANCOS | D10: 1 | E10: 7 | G10: ='[1]LIBRO DIARIO'!G36 -> 81987.889 | H10: =(H9+F10)-G10 -> 77359.241 | J10: ='[1]LIBRO DIARIO'!B42 -> 46035 | K10: A PROVEEDORES | L10: 1 | M10: 8 | N10: ='[1]LIBRO DIARIO'!F43 -> 67500 | P10: =(P9+N10)-O10 -> 102093.28
B11: ='[1]LIBRO DIARIO'!B46 -> 46037 | C11: A VENTAS | D11: 1 | E11: 9 | F11: ='[1]LIBRO DIARIO'!F47 -> 44624.035 | H11: =(H10+F11)-G11 -> 121983.28 | J11: ='[1]LIBRO DIARIO'!B46 -> 46037 | K11: POR COSTO DE VENTAS | L11: 1 | M11: 10 | O11: ='[1]LIBRO DIARIO'!G53 -> 69725.054 | P11: =(P10+N11)-O11 -> 32368.223
F13: =SUM(F7:F11) -> 208285.15 | G13: =SUM(G7:G11) -> 86301.87 | H13: =SUM(H7:H11) -> 514375.67 | N13: =SUM(N7:N12) -> 179347.92 | O13: =SUM(O7:O12) -> 146979.7 | P13: =SUM(P7:P12) -> 304302.7
B16: Industrias "ALAN SPORT" | J16: Industrias "ALAN SPORT"
B17: LIBRO MAYOR | J17: LIBRO MAYOR
B18: CUENTA | C18: ='LIBRO DIARIO'!C10 -> INV. MATERIA PRIMA INDIRECTA | G18: No | H18: 3 | J18: CUENTA | K18: ='LIBRO DIARIO'!C11 -> MAQUINARIA | O18: No | P18: 4
B19: FECHA | C19: DETALLE | D19: F | E19: A | F19: DEBE | G19: HABER | H19: SALDO | J19: FECHA | K19: DETALLE | L19: F | M19: A | N19: DEBE | O19: HABER | P19: SALDO
B20: ='LIBRO DIARIO'!B7 -> 46027 | C20: A VARIOS | D20: 1 | E20: 1 | F20: ='LIBRO DIARIO'!F10 -> 300 | H20: =F20-G20 -> 300 | J20: ='LIBRO DIARIO'!B7 -> 46027 | K20: A VARIOS | L20: 1 | M20: 1 | N20: ='LIBRO DIARIO'!F11 -> 70000 | P20: =N20-O20 -> 70000
B21: ='LIBRO DIARIO'!B15 -> 46027 | C21: A PROVEEDORES | D21: 1 | E21: 2 | F21: ='LIBRO DIARIO'!F17 -> 0 | H21: =(H20+F21)-G21 -> 300 | J21: ='[1]LIBRO DIARIO'!B15 -> 46027 | K21: POR MERCADERÍAS | L21: 1 | M21: 3 | O21: ='[1]LIBRO DIARIO'!G17 -> 14850 | P21: =(P20+N21)-O21 -> 55150
B22: ='LIBRO DIARIO'!B20 -> 46027 | C22: POR PRODUCCIÓN. PROCESO | D22: 1 | E22: 3 | G22: ='LIBRO DIARIO'!G25 -> 76 | H22: =(H21+F22)-G22 -> 224 | J22: ='[1]LIBRO DIARIO'!B20 -> 46028 | K22: POR VARIOS | L22: 1 | M22: 3 | O22: ='[1]LIBRO DIARIO'!G24 -> 5800 | P22: =(P21+N22)-O22 -> 49350
J23: ='[1]LIBRO DIARIO'!B26 -> 46030 | K23: A CAJA | L23: 1 | M23: 7 | N23: ='[1]LIBRO DIARIO'!F35 -> 81987.889 | P23: =(P22+N23)-O23 -> 131337.89
J24: ='[1]LIBRO DIARIO'!B38 -> 46034 | K24: POR VEHÍCULOS | L24: 1 | M24: 5 | O24: ='[1]LIBRO DIARIO'!G40 -> 22000 | P24: =(P23+N24)-O24 -> 109337.89
J25: ='[1]LIBRO DIARIO'!B55 -> 46052 | K25: POR GASTO ARRIENDO | L25: 1 | M25: 11 | O25: ='[1]LIBRO DIARIO'!G57 -> 1200 | P25: =(P24+N25)-O25 -> 108137.89
J26: ='[1]LIBRO DIARIO'!B59 -> 46052 | K26: POR GATOS SUELDOS | L26: 1 | M26: 12 | O26: ='[1]LIBRO DIARIO'!G62 -> 5984.046 | P26: =(P25+N26)-O26 -> 102153.84
F27: =SUM(F20:F25) -> 300 | G27: =SUM(G20:G25) -> 76 | H27: =SUM(H20:H25) -> 824 | N27: =SUM(N20:N26) -> 151987.89 | O27: =SUM(O20:O26) -> 49834.046 | P27: =SUM(P20:P26) -> 625467.51
B30: Industrias "ALAN SPORT" | J30: Industrias "ALAN SPORT"
B31: LIBRO MAYOR | J31: LIBRO MAYOR
B32: CUENTA | C32: ='LIBRO DIARIO'!C12 -> PROVEEDORES | G32: No | H32: 5 | J32: CUENTA | K32: ='LIBRO DIARIO'!C13 -> CAPITAL | O32: No | P32: 6
B33: FECHA | C33: DETALLE | D33: F | E33: A | F33: DEBE | G33: HABER | H33: SALDO | J33: FECHA | K33: DETALLE | L33: F | M33: A | N33: DEBE | O33: HABER | P33: SALDO
B34: ='LIBRO DIARIO'!B7 -> 46027 | C34: POR VARIOS | D34: 1 | E34: 1 | F34: ='[1]LIBRO DIARIO'!F33 -> 0 | G34: ='LIBRO DIARIO'!G12 -> 15000 | H34: =G34-F34 -> 15000 | J34: ='LIBRO DIARIO'!B7 -> 46027 | K34: POR VARIOS | L34: 1 | M34: 1 | O34: ='LIBRO DIARIO'!G13 -> 158700 | P34: =O34-N34 -> 158700
B35: ='LIBRO DIARIO'!B15 -> 46027 | C35: POR VARIOS | D35: 1 | E35: 2 | G35: ='LIBRO DIARIO'!G18 -> 88447.92 | H35: =H34+G35-F35 -> 103447.92
F40: =SUM(F34:F39) -> 0 | G40: =SUM(G34:G39) -> 103447.92 | H40: =SUM(H34:H39) -> 118447.92 | N40: =SUM(N34:N39) -> 0 | O40: =SUM(O34:O39) -> 158700 | P40: =SUM(P34:P39) -> 158700
B43: Industrias "ALAN SPORT" | J43: Industrias "ALAN SPORT"
B44: LIBRO MAYOR | J44: LIBRO MAYOR
B45: CUENTA | C45: ='LIBRO DIARIO'!C21 -> PRODUCCIÓN PROCESO OP#100 TS | G45: No | H45: 7 | J45: CUENTA | K45: ='LIBRO DIARIO'!C38 -> PRODUCCIÓN PROCESO OP#100 TM | O45: No | P45: 8
B46: FECHA | C46: DETALLE | D46: F | E46: A | F46: DEBE | G46: HABER | H46: SALDO | J46: FECHA | K46: DETALLE | L46: F | M46: A | N46: DEBE | O46: HABER | P46: SALDO
B47: ='LIBRO DIARIO'!B20 -> 46027 | C47: A VARIOS | D47: 1 | E47: 3 | F47: ='LIBRO DIARIO'!F21 -> 18807.53 | G47: ='[1]LIBRO DIARIO'!G30 -> 0 | H47: =F47-G47 -> 18807.53 | J47: ='LIBRO DIARIO'!B20 -> 46027 | K47: A VARIOS | L47: 1 | M47: 3 | N47: ='LIBRO DIARIO'!F22 -> 30931.778 | O47: ='[1]LIBRO DIARIO'!O30 -> 0 | P47: =N47-O47 -> 30931.778
B48: ='LIBRO DIARIO'!B36 -> 46031 | C48: A MOD Y MOI | D48: 1 | E48: 5 | F48: ='LIBRO DIARIO'!F37 -> 1545.52 | H48: =(H47+F48)-G48 -> 20353.05 | J48: ='LIBRO DIARIO'!B36 -> 46031 | K48: A MOD Y MOI | L48: 1 | M48: 5 | N48: ='LIBRO DIARIO'!F38 -> 2472.8319 | P48: =(P47+N48)-O48 -> 33404.61
B49: ='LIBRO DIARIO'!B52 -> 46036 | C49: A MOD Y MOI | D49: 1 | E49: 7 | F49: ='LIBRO DIARIO'!F53 -> 927.31198 | H49: =(H48+F49)-G49 -> 21280.362 | J49: ='LIBRO DIARIO'!B52 -> 46036 | K49: A MOD Y MOI | L49: 1 | M49: 7 | N49: ='LIBRO DIARIO'!F54 -> 1483.6992 | P49: =(P48+N49)-O49 -> 34888.309
B50: ='LIBRO DIARIO'!B74 -> 46036 | C50: A CIF | D50: 1 | E50: 10 | F50: ='LIBRO DIARIO'!F75 -> 218.33333 | H50: =(H49+F50)-G50 -> 21498.695 | J50: ='LIBRO DIARIO'!B74 -> 46036 | K50: A CIF | L50: 1 | M50: 10 | N50: ='LIBRO DIARIO'!F76 -> 327.5 | P50: =(P49+N50)-O50 -> 35215.809
B51: ='LIBRO DIARIO'!B80 -> 46036 | C51: POR PRO. TERMINADOS TS | D51: 1 | E51: 11 | G51: ='LIBRO DIARIO'!G84 -> 21498.695 | H51: =(H50+F51)-G51 -> 0 | J51: ='LIBRO DIARIO'!B80 -> 46036 | K51: POR PRO. TERMINADOS TM | L51: 1 | M51: 11 | O51: ='LIBRO DIARIO'!G85 -> 35215.809 | P51: =(P50+N51)-O51 -> 0
H52: =(H51+F52)-G52 -> 0
H53: =(H52+F53)-G53 -> 0
...

Sheet HOJA DE COSTOS
B3: INDUSTRIAS "ALAN SPORT" | H3: INDUSTRIAS "ALAN SPORT" | N3: INDUSTRIAS "ALAN SPORT"
B4: HOJA DE COSTOS | H4: HOJA DE COSTOS | N4: HOJA DE COSTOS
B5: NÚMERO: | D5: 10 | H5: NÚMERO: | J5: 10 | N5: NÚMERO: | P5: 10
B6: ORDEN DE PRODUCCIÓN: | D6: 100 | H6: ORDEN DE PRODUCCIÓN: | J6: 100 | N6: ORDEN DE PRODUCCIÓN: | P6: 100
B7: CLIENTE: | D7: TOMY | H7: CLIENTE: | J7: TOMY | N7: CLIENTE: | P7: TOMY
B8: PRODUCTO: | D8: ='ORDEN P'!C10 -> CAMISETA S | H8: PRODUCTO: | J8: ='ORDEN P'!C11 -> CAMISETA M | N8: PRODUCTO: | P8: ='ORDEN P'!C12 -> CAMISETA L
B9: CANTIDAD: | D9: ='ORDEN P'!B10 -> 4000 | H9: CANTIDAD: | J9: ='ORDEN P'!B11 -> 6000 | N9: CANTIDAD: | P9: ='ORDEN P'!B12 -> 5000
B10: FECHA DE INICIO: | D10: 46027 | H10: FECHA DE INICIO: | J10: 46027 | N10: FECHA DE INICIO: | P10: 46027
B11: FECHA TERMINO: | D11: =KARDEX!B116 -> 46036 | H11: FECHA TERMINO: | J11: 46036 | N11: FECHA TERMINO: | P11: =KARDEX!N116 -> 0
B13: MATERIA PRIMA DIRECTA | H13: MATERIA PRIMA DIRECTA | N13: MATERIA PRIMA DIRECTA
B14: FACHA | C14: DETALLE | D14: CANTIDAD | E14: V.UNITARIO | F14: V.TOTAL | H14: FACHA | I14: DETALLE | J14: CANTIDAD | K14: V.UNITARIO | L14: V.TOTAL | N14: FACHA | O14: DETALLE | P14: CANTIDAD | Q14: V.UNITARIO | R14: V.TOTAL
B15: =KARDEX!B11 -> 46027 | C15: =KARDEX!C5 -> TELA PIQUET | D15: ='HOJA DE COSTOS'!D9 -> 4000 | E15: =F15/D15 -> 3.619311 | F15: =KARDEX!I11 -> 14477.244 | H15: =B15 -> 46027 | I15: =C15 -> TELA PIQUET | J15: ='HOJA DE COSTOS'!J9 -> 6000 | K15: =L15/J15 -> 4.0717249 | L15: =KARDEX!I12 -> 24430.349 | N15: =B15 -> 46027 | O15: =C15 -> TELA PIQUET | P15: ='HOJA DE COSTOS'!P9 -> 5000 | Q15: =R15/P15 -> 4.9765526 | R15: =KARDEX!I13 -> 24882.763
B16: =KARDEX!B27 -> 46027 | C16: =KARDEX!C21 -> CUELLOS | D16: =D9 -> 4000 | E16: =F16/D16 -> 0.54285714 | F16: =KARDEX!I27 -> 2171.4286 | H16: =B16 -> 46027 | I16: =C16 -> CUELLOS | J16: =J9 -> 6000 | K16: =L16/J16 -> 0.54285714 | L16: =KARDEX!I28 -> 3257.1429 | N16: =B16 -> 46027 | O16: =C16 -> CUELLOS | P16: =P9 -> 5000 | Q16: =R16/P16 -> 0.54285714 | R16: =KARDEX!I29 -> 2714.2857
B17: =KARDEX!B43 -> 46027 | C17: =KARDEX!C37 -> PUÑOS | D17: =D9 -> 4000 | E17: =F17/D17 -> 0.4352381 | F17: =KARDEX!I43 -> 1740.9524 | H17: =B17 -> 46027 | I17: =C17 -> PUÑOS | J17: =J9 -> 6000 | K17: =L17/J17 -> 0.4352381 | L17: =KARDEX!I44 -> 2611.4286 | N17: =B17 -> 46027 | O17: =C17 -> PUÑOS | P17: =P9 -> 5000 | Q17: =R17/P17 -> 0.4352381 | R17: =KARDEX!I45 -> 2176.1905
B18: =KARDEX!B59 -> 46027 | C18: =KARDEX!C53 -> BOTÓN | D18: =D9 -> 4000 | E18: =F18/D18 -> 0.10047619 | F18: =KARDEX!I59 -> 401.90476 | H18: =B18 -> 46027 | I18: =C18 -> BOTÓN | J18: =J9 -> 6000 | K18: =L18/J18 -> 0.10047619 | L18: =KARDEX!I60 -> 602.85714 | N18: =B18 -> 46027 | O18: =C18 -> BOTÓN | P18: =P9 -> 5000 | Q18: =R18/P18 -> 0.10047619 | R18: =KARDEX!I61 -> 502.38095
E19: SUBTOTAL: | F19: =SUM(F15:F18) -> 18791.53 | K19: SUBTOTAL: | L19: =SUM(L15:L18) -> 30901.778 | Q19: SUBTOTAL: | R19: =SUM(R15:R18) -> 30275.62
B21: MATERIA DE OBRA DIRECTA | H21: MATERIA DE OBRA DIRECTA | N21: MATERIA DE OBRA DIRECTA
B22: FACHA | C22: DETALLE | D22: CANTIDAD | E22: V.UNITARIO | F22: V.TOTAL | H22: FACHA | I22: DETALLE | J22: CANTIDAD | K22: V.UNITARIO | L22: V.TOTAL | N22: FACHA | O22: DETALLE | P22: CANTIDAD | Q22: V.UNITARIO | R22: V.TOTAL
B23: =MAYORIZACIÓN!J61 -> 46031 | C23: DEL 5 AL 9 DE ENERO | D23: =D9 -> 4000 | E23: =F23/D23 -> 0.34989199 | F23: ='LIBRO DIARIO'!G40*25% -> 1399.568 | H23: =B23 -> 46031 | I23: DEL 5 AL 9 DE ENERO | J23: =J9 -> 6000 | K23: =L23/J23 -> 0.37321812 | L23: ='LIBRO DIARIO'!G40*40% -> 2239.3087 | N23: =B23 -> 46031 | O23: DEL 5 AL 9 DE ENERO | P23: =P9 -> 5000 | Q23: =R23/P23 -> 0.39187903 | R23: ='LIBRO DIARIO'!G40*35% -> 1959.3951
B24: ='LIBRO DIARIO'!B43 -> 46036 | C24: DEL 12 AL 14 DE ENERO | D24: =D9 -> 4000 | E24: =F24/D24 -> 0.20993519 | F24: ='LIBRO DIARIO'!G56*25% -> 839.74078 | H24: =B24 -> 46036 | I24: DEL 12 AL 14 DE ENERO | J24: =J9 -> 6000 | K24: =L24/J24 -> 0.22393087 | L24: ='LIBRO DIARIO'!F44*40% -> 1343.5852 | N24: =B24 -> 46036 | O24: DEL 12 AL 14 DE ENERO | P24: =P9 -> 5000 | Q24: =R24/P24 -> 0.23512742 | R24: ='LIBRO DIARIO'!G56*35% -> 1175.6371
E25: SUBTOTAL: | F25: =SUM(F23:F24) -> 2239.3087 | K25: SUBTOTAL: | L25: =SUM(L23:L24) -> 3582.894 | Q25: SUBTOTAL: | R25: =SUM(R23:R24) -> 3135.0322
B27: COSTOS INDIRECTOS DE FÀBRICA | H27: COSTOS INDIRECTOS DE FÀBRICA | N27: COSTOS INDIRECTOS DE FÀBRICA
B28: FACHA | C28: DETALLE | D28: CANTIDAD | E28: V.UNITARIO | F28: V.TOTAL | H28: FACHA | I28: DETALLE | J28: CANTIDAD | K28: V.UNITARIO | L28: V.TOTAL | N28: FACHA | O28: DETALLE | P28: CANTIDAD | Q28: V.UNITARIO | R28: V.TOTAL
B29: =KARDEX!B75 -> 46027 | C29: =KARDEX!C69 -> HILO | D29: =D9 -> 4000 | E29: =F29/D29 -> 0.004 | F29: =KARDEX!I75 -> 16 | H29: =B29 -> 46027 | I29: =C29 -> HILO | J29: =J9 -> 6000 | K29: =L29/J29 -> 0.005 | L29: =KARDEX!I76 -> 30 | N29: =B29 -> 46027 | O29: HILO | P29: =P9 -> 5000 | Q29: =R29/P29 -> 0.006 | R29: =KARDEX!I77 -> 30
B30: =MAYORIZACIÓN!B75 -> 46031 | C30: MOI | D30: =D9 -> 4000 | E30: =F30/D30 -> 0.036488 | F30: ='LIBRO DIARIO'!F29*25% -> 145.952 | H30: =B30 -> 46031 | I30: =C30 -> MOI | J30: =J9 -> 6000 | K30: =L30/J30 -> 0.038920533 | L30: ='LIBRO DIARIO'!F29*40% -> 233.5232 | N30: =B30 -> 46031 | O30: MOI | P30: =P9 -> 5000 | Q30: =R30/P30 -> 0.04086656 | R30: ='LIBRO DIARIO'!F29*35% -> 204.3328
B31: ='LIBRO DIARIO'!B43 -> 46036 | C31: MOI | D31: =D9 -> 4000 | E31: =F31/D31 -> 0.0218928 | F31: ='LIBRO DIARIO'!F45*25% -> 87.571199 | H31: =B31 -> 46036 | I31: =C31 -> MOI | J31: =J9 -> 6000 | K31: =L31/J31 -> 0.02335232 | L31: ='LIBRO DIARIO'!F45*40% -> 140.11392 | N31: =B31 -> 46036 | O31: =C31 -> MOI | P31: =P9 -> 5000 | Q31: =R31/P31 -> 0.024519936 | R31: ='LIBRO DIARIO'!F45*35% -> 122.59968
B32: ='LIBRO DIARIO'!B43 -> 46036 | C32: =CÁLCULOS!B64 -> ENERGÍA ELÉCTRICA | D32: =D9 -> 4000 | E32: =F32/D32 -> 0.0125 | F32: =CÁLCULOS!G64 -> 50 | H32: =B32 -> 46036 | I32: =C32 -> ENERGÍA ELÉCTRICA | J32: =J9 -> 6000 | K32: =L32/J32 -> 0.0125 | L32: =CÁLCULOS!H64 -> 75 | N32: =B32 -> 46036 | O32: =C32 -> ENERGÍA ELÉCTRICA | P32: =P9 -> 5000 | Q32: =R32/P32 -> 0.0125 | R32: =CÁLCULOS!I64 -> 62.5
B33: ='LIBRO DIARIO'!B43 -> 46036 | C33: =CÁLCULOS!B65 -> MANTENIMIENTO | D33: =D9 -> 4000 | E33: =F33/D33 -> 0.01875 | F33: =CÁLCULOS!G65 -> 75 | H33: =B33 -> 46036 | I33: =C33 -> MANTENIMIENTO | J33: =J9 -> 6000 | K33: =L33/J33 -> 0.01875 | L33: =CÁLCULOS!H65 -> 112.5 | N33: =B33 -> 46036 | O33: =C33 -> MANTENIMIENTO | P33: =P9 -> 5000 | Q33: =R33/P33 -> 0.01875 | R33: =CÁLCULOS!I65 -> 93.75
B34: ='LIBRO DIARIO'!B43 -> 46036 | C34: =CÁLCULOS!B66 -> SEGUROS DE FÁBRICA | D34: =D9 -> 4000 | E34: =F34/D34 -> 0.00875 | F34: =CÁLCULOS!G66 -> 35 | H34: =B34 -> 46036 | I34: =C34 -> SEGUROS DE FÁBRICA | J34: =J9 -> 6000 | K34: =L34/J34 -> 0.00875 | L34: =CÁLCULOS!H66 -> 52.5 | N34: =B34 -> 46036 | O34: =C34 -> SEGUROS DE FÁBRICA | P34: =P9 -> 5000 | Q34: =R34/P34 -> 0.00875 | R34: =CÁLCULOS!I66 -> 43.75
B35: ='LIBRO DIARIO'!B43 -> 46036 | C35: =CÁLCULOS!B67 -> DEPRECIACIÓN MAQUINARIA | D35: =D9 -> 4000 | E35: =F35/D35 -> 0.014583333 | F35: =CÁLCULOS!G67 -> 58.333333 | H35: =B35 -> 46036 | I35: =C35 -> DEPRECIACIÓN MAQUINARIA | J35: =J9 -> 6000 | K35: =L35/J35 -> 0.014583333 | L35: =CÁLCULOS!H67 -> 87.5 | N35: =B35 -> 46036 | O35: =C35 -> DEPRECIACIÓN MAQUINARIA | P35: =P9 -> 5000 | Q35: =R35/P35 -> 0.014583333 | R35: =CÁLCULOS!I67 -> 72.916667
E36: SUBTOTAL: | F36: =SUM(F29:F35) -> 467.85653 | K36: SUBTOTAL: | L36: =SUM(L29:L35) -> 731.13712 | Q36: SUBTOTAL: | R36: =SUM(R29:R35) -> 629.84914
C38: COSTO TOTAL DE PRODUCCIÓN: | F38: =F19+F25+F36 -> 21498.695 | I38: COSTO TOTAL DE PRODUCCIÓN: | L38: =L19+L25+L36 -> 35215.809 | O38: COSTO TOTAL DE PRODUCCIÓN: | R38: =R19+R25+R36 -> 34040.502
C39: UNIDADES PRODUCIDAS: | F39: =D9 -> 4000 | I39: UNIDADES PRODUCIDAS: | L39: =J9 -> 6000 | O39: UNIDADES PRODUCIDAS: | R39: =P9 -> 5000
C40: COSTO UNITARIO: | F40: =F38/F39 -> 5.3746738 | I40: COSTO UNITARIO: | L40: =L38/L39 -> 5.8693015 | O40: COSTO UNITARIO: | R40: =R38/R39 -> 6.8081004
B44: INDUSTRIAS "ALAN SPORT"
B45: HOJA DE COSTOS
B46: NÚMERO: | D46: 11
B47: ORDEN DE PRODUCCIÓN: | D47: ='ORDEN P'!G4 -> 101
B48: CLIENTE: | D48: ='ORDEN P'!G5 -> TEXPAX
B49: PRODUCTO: | D49: ='ORDEN P'!G10 -> CAMISETA S
...

Sheet KARDEX
B2: INDUSTRIAS "ALAN SPORT"
B3: KARDEX
B5: PRODUCTO: | C5: TELA PIQUET
B6: UNIDAD MEDIA: METROS | F6: MÉTODO: | H6: PROMEDIO | K6: No. | L6: 1
D7: ENTRADAS | G7: SALIDAS | J7: SALDOS
B8: FECHA | C8: DETALLE | D8: CANT. | E8: V.UNI | F8: V.TOTAL | G8: CANT. | H8: V.UNI | I8: V.TOTAL | J8: CANT. | K8: V.UNI | L8: V.TOTAL
B9: ='LIBRO DIARIO'!B7 -> 46027 | C9: SITUACIÓN INICIA DE LA INDUSTRIA | D9: 4500 | E9: 4.2 | F9: =D9*E9 -> 18900 | J9: =D9-G9 -> 4500 | K9: =L9/J9 -> 4.2 | L9: =F9-I9 -> 18900
B10: 46027 | C10: COMPRA SEGÙN FACTURA PARA OP#100 | D10: =CÁLCULOS!J9 -> 15216 | E10: =E9*1.1 -> 4.62 | F10: =D10*E10 -> 70297.92 | J10: =J9+D10-G10 -> 19716 | K10: =L10/J10 -> 4.5241388 | L10: =L9+F10-I10 -> 89197.92
B11: 46027 | C11: ENVIO A PRODUCCIÓN OP#100 TS | G11: =CÁLCULOS!F5 -> 3200 | H11: =K10 -> 4.5241388 | I11: =G11*H11 -> 14477.244 | J11: =J10+D11-G11 -> 16516 | K11: =L11/J11 -> 4.5241388 | L11: =L10+F11-I11 -> 74720.676
B12: 46027 | C12: ENVIO A PRODUCCIÓN OP#100 TM | G12: =CÁLCULOS!F6 -> 5400 | H12: =K11 -> 4.5241388 | I12: =G12*H12 -> 24430.349 | J12: =J11+D12-G12 -> 11116 | K12: =L12/J12 -> 4.5241388 | L12: =L11+F12-I12 -> 50290.327
B13: 46027 | C13: ENVIO A PRODUCCIÓN OP#100 TL | G13: =CÁLCULOS!F7 -> 5500 | H13: =K12 -> 4.5241388 | I13: =G13*H13 -> 24882.763 | J13: =J12+D13-G13 -> 5616 | K13: =L13/J13 -> 4.5241388 | L13: =L12+F13-I13 -> 25407.563
B14: ='LIBRO DIARIO'!B98 -> 46037 | C14: COMPRA SEGÙN FACTURA PARA OP#101 | D14: =CÁLCULOS!E86 -> 19300 | E14: =E10*1.1 -> 5.082 | F14: =D14*E14 -> 98082.6 | J14: =J13+D14-G14 -> 24916 | K14: =L14/J14 -> 4.9562596 | L14: =L13+F14-I14 -> 123490.16
B15: ='LIBRO DIARIO'!B98 -> 46037 | C15: ENVIO A PRODUCCIÓN OP#101 TS | G15: =CÁLCULOS!F82 -> 4000 | H15: =K14 -> 4.9562596 | I15: =G15*H15 -> 19825.038 | J15: =J14+D15-G15 -> 20916 | K15: =L15/J15 -> 4.9562596 | L15: =L14+F15-I15 -> 103665.13
B16: ='LIBRO DIARIO'!B98 -> 46037 | C16: ENVIO A PRODUCCIÓN OP#101 TM | G16: =CÁLCULOS!F83 -> 5400 | H16: =K15 -> 4.9562596 | I16: =G16*H16 -> 26763.802 | J16: =J15+D16-G16 -> 15516 | K16: =L16/J16 -> 4.9562596 | L16: =L15+F16-I16 -> 76901.323
B17: ='LIBRO DIARIO'!B98 -> 46037 | C17: ENVIO A PRODUCCIÓN OP#101 TL | G17: =CÁLCULOS!F84 -> 9900 | H17: =K16 -> 4.9562596 | I17: =G17*H17 -> 49066.97 | J17: =J16+D17-G17 -> 5616 | K17: =L17/J17 -> 4.9562596 | L17: =L16+F17-I17 -> 27834.354
B21: PRODUCTO: | C21: CUELLOS
B22: UNIDAD MEDIA: UNITARIO | F22: MÉTODO: | H22: PROMEDIO | K22: No. | L22: 2
D23: ENTRADAS | G23: SALIDAS | J23: SALDOS
B24: FECHA | C24: DETALLE | D24: CANT. | E24: V.UNI | F24: V.TOTAL | G24: CANT. | H24: V.UNI | I24: V.TOTAL | J24: CANT. | K24: V.UNI | L24: V.TOTAL
B25: ='LIBRO DIARIO'!B7 -> 46027 | C25: SITUACIÓN INICIA DE LA INDUSTRIA | D25: 3000 | E25: 0.5 | F25: =D25*E25 -> 1500 | J25: =D25-G25 -> 3000 | K25: =L25/J25 -> 0.5 | L25: =F25-I25 -> 1500
B26: 46027 | C26: COMPRA SEGÙN FACTURA PARA OP#100 | D26: =CÁLCULOS!J18 -> 18000 | E26: =E25*1.1 -> 0.55 | F26: =D26*E26 -> 9900 | J26: =J25+D26-G26 -> 21000 | K26: =L26/J26 -> 0.54285714 | L26: =L25+F26-I26 -> 11400
B27: 46027 | C27: ENVIO A PRODUCCIÓN OP#100 TS | G27: =CÁLCULOS!E15 -> 4000 | H27: =K26 -> 0.54285714 | I27: =G27*H27 -> 2171.4286 | J27: =J26+D27-G27 -> 17000 | K27: =L27/J27 -> 0.54285714 | L27: =L26+F27-I27 -> 9228.5714
B28: 46027 | C28: ENVIO A PRODUCCIÓN OP#100 TM | G28: =CÁLCULOS!E16 -> 6000 | H28: =K27 -> 0.54285714 | I28: =G28*H28 -> 3257.1429 | J28: =J27+D28-G28 -> 11000 | K28: =L28/J28 -> 0.54285714 | L28: =L27+F28-I28 -> 5971.4286
B29: 46027 | C29: ENVIO A PRODUCCIÓN OP#100 TL | G29: =CÁLCULOS!E17 -> 5000 | H29: =K28 -> 0.54285714 | I29: =G29*H29 -> 2714.2857 | J29: =J28+D29-G29 -> 6000 | K29: =L29/J29 -> 0.54285714 | L29: =L28+F29-I29 -> 3257.1429
B30: ='LIBRO DIARIO'!B98 -> 46037 | C30: COMPRA SEGÙN FACTURA PARA OP#101 | D30: =CÁLCULOS!J95 -> 20000 | E30: =E26*1.1 -> 0.605 | F30: =D30*E30 -> 12100 | J30: =J29+D30-G30 -> 26000 | K30: =L30/J30 -> 0.59065934 | L30: =L29+F30-I30 -> 15357.143
B31: ='LIBRO DIARIO'!B98 -> 46037 | C31: ENVIO A PRODUCCIÓN OP#100 TS | G31: =CÁLCULOS!E92 -> 5000 | H31: =K30 -> 0.59065934 | I31: =G31*H31 -> 2953.2967 | J31: =J30+D31-G31 -> 21000 | K31: =L31/J31 -> 0.59065934 | L31: =L30+F31-I31 -> 12403.846
B32: ='LIBRO DIARIO'!B98 -> 46037 | C32: ENVIO A PRODUCCIÓN OP#100 TM | G32: =CÁLCULOS!E93 -> 6000 | H32: =K31 -> 0.59065934 | I32: =G32*H32 -> 3543.956 | J32: =J31+D32-G32 -> 15000 | K32: =L32/J32 -> 0.59065934 | L32: =L31+F32-I32 -> 8859.8901
B33: ='LIBRO DIARIO'!B98 -> 46037 | C33: ENVIO A PRODUCCIÓN OP#100 TL | G33: =CÁLCULOS!E94 -> 9000 | H33: =K32 -> 0.59065934 | I33: =G33*H33 -> 5315.9341 | J33: =J32+D33-G33 -> 6000 | K33: =L33/J33 -> 0.59065934 | L33: =L32+F33-I33 -> 3543.956
B37: PRODUCTO: | C37: PUÑOS
B38: UNIDAD MEDIA: UNITARIO | F38: MÉTODO: | H38: PROMEDIO | K38: No. | L38: 3
D39: ENTRADAS | G39: SALIDAS | J39: SALDOS
B40: FECHA | C40: DETALLE | D40: CANT. | E40: V.UNI | F40: V.TOTAL | G40: CANT. | H40: V.UNI | I40: V.TOTAL | J40: CANT. | K40: V.UNI | L40: V.TOTAL
B41: ='LIBRO DIARIO'!B7 -> 46027 | C41: SITUACIÓN INICIA DE LA INDUSTRIA | D41: 5000 | E41: 0.2 | F41: =D41*E41 -> 1000 | J41: =D41-G41 -> 5000 | K41: =L41/J41 -> 0.2 | L41: =F41-I41 -> 1000
B42: 46027 | C42: COMPRA SEGÙN FACTURA PARA OP#100 | D42: =CÁLCULOS!J27 -> 37000 | E42: =E41*1.1 -> 0.22 | F42: =D42*E42 -> 8140 | J42: =J41+D42-G42 -> 42000 | K42: =L42/J42 -> 0.21761905 | L42: =L41+F42-I42 -> 9140
B43: 46027 | C43: ENVIO A PRODUCCIÓN OP#100 TS | G43: =CÁLCULOS!E24 -> 8000 | H43: =K42 -> 0.21761905 | I43: =G43*H43 -> 1740.9524 | J43: =J42+D43-G43 -> 34000 | K43: =L43/J43 -> 0.21761905 | L43: =L42+F43-I43 -> 7399.0476
B44: 46027 | C44: ENVIO A PRODUCCIÓN OP#100 TM | G44: =CÁLCULOS!E25 -> 12000 | H44: =K43 -> 0.21761905 | I44: =G44*H44 -> 2611.4286 | J44: =J43+D44-G44 -> 22000 | K44: =L44/J44 -> 0.21761905 | L44: =L43+F44-I44 -> 4787.619
B45: 46027 | C45: ENVIO A PRODUCCIÓN OP#100 TL | G45: =CÁLCULOS!E26 -> 10000 | H45: =K44 -> 0.21761905 | I45: =G45*H45 -> 2176.1905 | J45: =J44+D45-G45 -> 12000 | K45: =L45/J45 -> 0.21761905 | L45: =L44+F45-I45 -> 2611.4286
B46: ='LIBRO DIARIO'!B98 -> 46037 | C46: COMPRA SEGÙN FACTURA PARA OP#101 | D46: =CÁLCULOS!J104 -> 40000 | E46: =E42*1.1 -> 0.242 | F46: =D46*E46 -> 9680 | J46: =J45+D46-G46 -> 52000 | K46: =L46/J46 -> 0.23637363 | L46: =L45+F46-I46 -> 12291.429
B47: ='LIBRO DIARIO'!B98 -> 46037 | C47: ENVIO A PRODUCCIÓN OP#100 TS | G47: =CÁLCULOS!E101 -> 10000 | H47: =K46 -> 0.23637363 | I47: =G47*H47 -> 2363.7363 | J47: =J46+D47-G47 -> 42000 | K47: =L47/J47 -> 0.23637363 | L47: =L46+F47-I47 -> 9927.6923
B48: ='LIBRO DIARIO'!B98 -> 46037 | C48: ENVIO A PRODUCCIÓN OP#100 TM | G48: =CÁLCULOS!E102 -> 12000 | H48: =K47 -> 0.23637363 | I48: =G48*H48 -> 2836.4835 | J48: =J47+D48-G48 -> 30000 | K48: =L48/J48 -> 0.23637363 | L48: =L47+F48-I48 -> 7091.2088
...

Sheet CÁLCULOS
B2: MATERIA PRIMA DIRECTA
B3: TELA
B4: PRODUCTOS | C4: CANTIDAD | D4: REQUERIMIENTO | E4: TOTAL | G4: INVENTARIO | H4: COMPRA | I4: INV. FINAL | J4: COMPRA OPTIMA
B5: CAMISETA S | C5: ='ORDEN P'!B10 -> 4000 | D5: 80 | E5: =C5*D5 -> 320000 | F5: =E5/100 -> 3200
B6: CAMISETA L | C6: ='ORDEN P'!B11 -> 6000 | D6: 90 | E6: =C6*D6 -> 540000 | F6: =E6/100 -> 5400
B7: CAMISETA M | C7: ='ORDEN P'!B12 -> 5000 | D7: 110 | E7: =C7*D7 -> 550000 | F7: =E7/100 -> 5500
D8: CENTÍMETROS: | E8: =SUM(E5:E7) -> 1410000 | F8: =E8/100 -> 14100
D9: METRO: | E9: =E8/100 -> 14100 | G9: =KARDEX!J9 -> 4500 | H9: =E9-G9 -> 9600 | I9: =DATOS!F25 -> 5616 | J9: =H9+I9 -> 15216
B12: MATERIA PRIMA DIRECTA
B13: CUELLOS
B14: PRODUCTOS | C14: CANTIDAD | D14: REQUERIMIENTO | E14: TOTAL | G14: INVENTARIO | H14: COMPRA | I14: INV. FINAL | J14: COMPRA OPTIMA
B15: CAMISETA S | C15: ='ORDEN P'!B10 -> 4000 | D15: 1 | E15: =C15*D15 -> 4000
B16: CAMISETA L | C16: ='ORDEN P'!B11 -> 6000 | D16: 1 | E16: =C16*D16 -> 6000
B17: CAMISETA M | C17: ='ORDEN P'!B12 -> 5000 | D17: 1 | E17: =C17*D17 -> 5000
D18: UNIDADES: | E18: =SUM(E15:E17) -> 15000 | G18: =KARDEX!J25 -> 3000 | H18: =E18-G18 -> 12000 | I18: 6000 | J18: =H18+I18 -> 18000
B21: MATERIA PRIMA DIRECTA
B22: PUÑOS
B23: PRODUCTOS | C23: CANTIDAD | D23: REQUERIMIENTO | E23: TOTAL | G23: INVENTARIO | H23: COMPRA | I23: INV. FINAL | J23: COMPRA OPTIMA
B24: CAMISETA S | C24: ='ORDEN P'!B10 -> 4000 | D24: 2 | E24: =C24*D24 -> 8000
B25: CAMISETA L | C25: ='ORDEN P'!B11 -> 6000 | D25: 2 | E25: =C25*D25 -> 12000
B26: CAMISETA M | C26: ='ORDEN P'!B12 -> 5000 | D26: 2 | E26: =C26*D26 -> 10000
D27: UNIDADES: | E27: =SUM(E24:E26) -> 30000 | G27: =KARDEX!J41 -> 5000 | H27: =E27-G27 -> 25000 | I27: 12000 | J27: =H27+I27 -> 37000
B30: MATERIA PRIMA DIRECTA
B31: BOTÓN
B32: PRODUCTOS | C32: CANTIDAD | D32: REQUERIMIENTO | E32: TOTAL | G32: INVENTARIO | H32: COMPRA | I32: INV. FINAL | J32: COMPRA OPTIMA
B33: CAMISETA S | C33: ='ORDEN P'!B10 -> 4000 | D33: 2 | E33: =C33*D33 -> 8000
B34: CAMISETA L | C34: ='ORDEN P'!B11 -> 6000 | D34: 2 | E34: =C34*D34 -> 12000
B35: CAMISETA M | C35: ='ORDEN P'!B12 -> 5000 | D35: 2 | E35: =C35*D35 -> 10000
D36: UNIDADES: | E36: =SUM(E33:E35) -> 30000 | G36: =KARDEX!J57 -> 40000 | H36: =E36-G36 -> -10000 | I36: 12000 | J36: =H36+I36 -> 2000
B39: MATERIA PRIMA DIRECTA
B40: HILO
B41: PRODUCTOS | C41: CANTIDAD | D41: REQUERIMIENTO | E41: TOTAL | G41: INVENTARIO | H41: COMPRA | I41: INV. FINAL | J41: COMPRA OPTIMA
B42: CAMISETA S | C42: ='ORDEN P'!B10 -> 4000 | D42: 4 | E42: =C42*D42 -> 16000
B43: CAMISETA L | C43: ='ORDEN P'!B11 -> 6000 | D43: 5 | E43: =C43*D43 -> 30000
B44: CAMISETA M | C44: ='ORDEN P'!B12 -> 5000 | D44: 6 | E44: =C44*D44 -> 30000
D45: METROS: | E45: =SUM(E42:E44) -> 76000 | G45: =KARDEX!J73 -> 300000 | H45: =E45-G45 -> -224000 | I45: 90000 | J45: =H45+I45 -> -134000
B47: MANO DE OBRA DIRECTA ene 2026
B49: L | C49: M | D49: M | E49: J | F49: V
B50: 5 | C50: 6 | D50: 7 | E50: 8 | F50: 9 | G50: OP #100
B51: 12 | C51: 13 | D51: 14 | E51: 15 | F51: 16
...

Sheet ORDEN P
B2: INDUSTRIAS "ALAN SPORT" | F2: INDUSTRIAS "ALAN SPORT"
B3: ORDEN DE PRODUCCIÓN | F3: ORDEN DE PRODUCCIÓN
B4: NÚMERO: | C4: 100 | F4: NÚMERO: | G4: 101
B5: CLIENTE | C5: TOMY | F5: CLIENTE | G5: TEXPAX
B6: FECHA DE INICIO | C6: 46027 | F6: FECHA DE INICIO | G6: 46037
B7: FECHA DE TERMINACIÓN: | F7: FECHA DE TERMINACIÓN:
B9: CANTIDAD | C9: PRODUCTO | D9: OBSERVACIÓN | F9: CANTIDAD | G9: PRODUCTO | H9: OBSERVACIÓN
B10: 4000 | C10: CAMISETA S | D10: CON BORDADO | F10: =DATOS!C52 -> 5000 | G10: CAMISETA S | H10: CON BORDADO
B11: 6000 | C11: CAMISETA M | D11: CON BORDADO | F11: =DATOS!C53 -> 6000 | G11: CAMISETA M | H11: CON BORDADO
B12: 5000 | C12: CAMISETA L | D12: CON BORDADO | F12: =DATOS!C54 -> 9000 | G12: CAMISETA L | H12: CON BORDADO
B13: =SUM(B10:B12) -> 15000 | F13: =SUM(F10:F12) -> 20000
B15: ….......................................... | D15: …............................... | F15: ….......................................... | H15: …...............................
B16: CLIENTE | D16: JEFE DE VENTAS | F16: CLIENTE | H16: JEFE DE VENTAS

Sheet ROL MOD
A2: ROL DE PAGOS
B3: MANO DE OBRA DIRECTA | H3: HORAS EXTRAS Y SUPLEMENTARIAS
A4: No. | B4: NOMBRES Y APELLIDOS | C4: CARGO | D4: FECHA INGRESO | E4: SUELDO | F4: DIAS TRABAJADOS | G4: SUELDO LIQUIDO | H4: 0.25 | I4: 0.5 | J4: 1 | K4: OTROS INGRESOS | L4: FONDO DE RESERVA | M4: TOTAL DE INGRESOS | N4: APORTE PERSONAL iess | O4: IMPUESTO RENTA | P4: RETENCIONES JUDICIALES | Q4: 0TROS DESCUENTOS | R4: TOTAL EGRESOS | S4: VALOR A RECIBIR
A5: 1 | B5: Alan Brito Delgado | C5: Obreros | D5: 45658 | E5: 482 | F5: 30 | G5: =(E5/30)*F5 -> 482 | H5: =((E5/160)*1.25)*0 -> 0 | I5: =((E5/160)*1.5)*4 -> 18.075 | J5: =((E5/160)*2)*8 -> 48.2 | L5: =(G5+H5+I5+J5+K5)/12 -> 45.689583 | M5: =+G5+H5+I5+J5+K5+L5 -> 593.96458 | N5: =(M5-L5)*9.45% -> 51.811988 | P5: 0 | R5: =+N5+O5+P5+Q5 -> 51.811988 | S5: =M5-R5 -> 542.1526
A6: 2 | B6: Nori Navas Robles | C6: Obreros | D6: 45659 | E6: 482 | F6: 30 | G6: =(E6/30)*F6 -> 482 | H6: =((E6/160)*1.25)*0 -> 0 | I6: =((E6/160)*1.5)*4 -> 18.075 | J6: =((E6/160)*2)*8 -> 48.2 | L6: =(G6+H6+I6+J6+K6)/12 -> 45.689583 | M6: =+G6+H6+I6+J6+K6+L6 -> 593.96458 | N6: =(M6-L6)*9.45% -> 51.811988 | P6: 0 | R6: =+N6+O6+P6+Q6 -> 51.811988 | S6: =M6-R6 -> 542.1526
A7: 3 | B7: Zoila Vaca Martinez | C7: Obreros | D7: 45660 | E7: 482 | F7: 30 | G7: =(E7/30)*F7 -> 482 | H7: =((E7/160)*1.25)*0 -> 0 | I7: =((E7/160)*1.5)*4 -> 18.075 | J7: =((E7/160)*2)*8 -> 48.2 | L7: =(G7+H7+I7+J7+K7)/12 -> 45.689583 | M7: =+G7+H7+I7+J7+K7+L7 -> 593.96458 | N7: =(M7-L7)*9.45% -> 51.811988 | P7: 0 | R7: =+N7+O7+P7+Q7 -> 51.811988 | S7: =M7-R7 -> 542.1526
A8: 4 | B8: Giuliana Armas | C8: Obreros | D8: 45661 | E8: 482 | F8: 30 | G8: =(E8/30)*F8 -> 482 | H8: =((E8/160)*1.25)*0 -> 0 | I8: =((E8/160)*1.5)*4 -> 18.075 | J8: =((E8/160)*2)*8 -> 48.2 | L8: =(G8+H8+I8+J8+K8)/12 -> 45.689583 | M8: =+G8+H8+I8+J8+K8+L8 -> 593.96458 | N8: =(M8-L8)*9.45% -> 51.811988 | P8: 0 | R8: =+N8+O8+P8+Q8 -> 51.811988 | S8: =M8-R8 -> 542.1526
A9: 5 | B9: Valeria Cortez | C9: Obreros | D9: 45662 | E9: 482 | F9: 30 | G9: =(E9/30)*F9 -> 482 | H9: =((E9/160)*1.25)*0 -> 0 | I9: =((E9/160)*1.5)*4 -> 18.075 | J9: =((E9/160)*2)*8 -> 48.2 | L9: =(G9+H9+I9+J9+K9)/12 -> 45.689583 | M9: =+G9+H9+I9+J9+K9+L9 -> 593.96458 | N9: =(M9-L9)*9.45% -> 51.811988 | P9: 0 | R9: =+N9+O9+P9+Q9 -> 51.811988 | S9: =M9-R9 -> 542.1526
A10: 6 | B10: Giuliana Armas | C10: Obreros | D10: 45663 | E10: 482 | F10: 30 | G10: =(E10/30)*F10 -> 482 | H10: =((E10/160)*1.25)*0 -> 0 | I10: =((E10/160)*1.5)*4 -> 18.075 | J10: =((E10/160)*2)*8 -> 48.2 | L10: =(G10+H10+I10+J10+K10)/12 -> 45.689583 | M10: =+G10+H10+I10+J10+K10+L10 -> 593.96458 | N10: =(M10-L10)*9.45% -> 51.811988 | P10: 0 | R10: =+N10+O10+P10+Q10 -> 51.811988 | S10: =M10-R10 -> 542.1526
A11: 7 | B11: Valeria Cortez | C11: Obreros | D11: 45664 | E11: 482 | F11: 30 | G11: =(E11/30)*F11 -> 482 | H11: =((E11/160)*1.25)*0 -> 0 | I11: =((E11/160)*1.5)*4 -> 18.075 | J11: =((E11/160)*2)*8 -> 48.2 | L11: =(G11+H11+I11+J11+K11)/12 -> 45.689583 | M11: =+G11+H11+I11+J11+K11+L11 -> 593.96458 | N11: =(M11-L11)*9.45% -> 51.811988 | P11: 0 | R11: =+N11+O11+P11+Q11 -> 51.811988 | S11: =M11-R11 -> 542.1526
A12: 8 | B12: Giuliana Armas | C12: Obreros | D12: 45665 | E12: 482 | F12: 30 | G12: =(E12/30)*F12 -> 482 | H12: =((E12/160)*1.25)*0 -> 0 | I12: =((E12/160)*1.5)*4 -> 18.075 | J12: =((E12/160)*2)*8 -> 48.2 | L12: =(G12+H12+I12+J12+K12)/12 -> 45.689583 | M12: =+G12+H12+I12+J12+K12+L12 -> 593.96458 | N12: =(M12-L12)*9.45% -> 51.811988 | P12: 0 | R12: =+N12+O12+P12+Q12 -> 51.811988 | S12: =M12-R12 -> 542.1526
A13: 9 | B13: Valeria Cortez | C13: Obreros | D13: 45666 | E13: 482 | F13: 30 | G13: =(E13/30)*F13 -> 482 | H13: =((E13/160)*1.25)*0 -> 0 | I13: =((E13/160)*1.5)*4 -> 18.075 | J13: =((E13/160)*2)*8 -> 48.2 | L13: =(G13+H13+I13+J13+K13)/12 -> 45.689583 | M13: =+G13+H13+I13+J13+K13+L13 -> 593.96458 | N13: =(M13-L13)*9.45% -> 51.811988 | P13: 0 | R13: =+N13+O13+P13+Q13 -> 51.811988 | S13: =M13-R13 -> 542.1526
A14: 10 | B14: Giuliana Armas | C14: Obreros | D14: 45667 | E14: 482 | F14: 30 | G14: =(E14/30)*F14 -> 482 | H14: =((E14/160)*1.25)*0 -> 0 | I14: =((E14/160)*1.5)*4 -> 18.075 | J14: =((E14/160)*2)*8 -> 48.2 | L14: =(G14+H14+I14+J14+K14)/12 -> 45.689583 | M14: =+G14+H14+I14+J14+K14+L14 -> 593.96458 | N14: =(M14-L14)*9.45% -> 51.811988 | P14: 0 | R14: =+N14+O14+P14+Q14 -> 51.811988 | S14: =M14-R14 -> 542.1526
A15: 11 | B15: Valeria Cortez | C15: Obreros | D15: 45668 | E15: 482 | F15: 30 | G15: =(E15/30)*F15 -> 482 | H15: =((E15/160)*1.25)*0 -> 0 | I15: =((E15/160)*1.5)*4 -> 18.075 | J15: =((E15/160)*2)*8 -> 48.2 | L15: =(G15+H15+I15+J15+K15)/12 -> 45.689583 | M15: =+G15+H15+I15+J15+K15+L15 -> 593.96458 | N15: =(M15-L15)*9.45% -> 51.811988 | P15: 0 | R15: =+N15+O15+P15+Q15 -> 51.811988 | S15: =M15-R15 -> 542.1526
A16: 12 | B16: Giuliana Armas | C16: Obreros | D16: 45669 | E16: 482 | F16: 30 | G16: =(E16/30)*F16 -> 482 | H16: =((E16/160)*1.25)*0 -> 0 | I16: =((E16/160)*1.5)*4 -> 18.075 | J16: =((E16/160)*2)*8 -> 48.2 | L16: =(G16+H16+I16+J16+K16)/12 -> 45.689583 | M16: =+G16+H16+I16+J16+K16+L16 -> 593.96458 | N16: =(M16-L16)*9.45% -> 51.811988 | P16: 0 | R16: =+N16+O16+P16+Q16 -> 51.811988 | S16: =M16-R16 -> 542.1526
... A19: 15 | B19: Valeria Cortez | C19: Obreros | D19: 45672 | E19: 482 | F19: 30 | G19: =(E19/30)*F19 -> 482 | H19: =((E19/160)*1.25)*0 -> 0 | I19: =((E19/160)*1.5)*4 -> 18.075 | J19: =((E19/160)*2)*8 -> 48.2 | L19: =(G19+H19+I19+J19+K19)/12 -> 45.689583 | M19: =+G19+H19+I19+J19+K19+L19 -> 593.96458 | N19: =(M19-L19)*9.45% -> 51.811988 | P19: 0 | R19: =+N19+O19+P19+Q19 -> 51.811988 | S19: =M19-R19 -> 542.1526
A20: 16 | B20: Giuliana Armas | C20: Obreros | D20: 45673 | E20: 482 | F20: 30 | G20: =(E20/30)*F20 -> 482 | H20: =((E20/160)*1.25)*0 -> 0 | I20: =((E20/160)*1.5)*4 -> 18.075 | J20: =((E20/160)*2)*8 -> 48.2 | L20: =(G20+H20+I20+J20+K20)/12*0 -> 0 | M20: =+G20+H20+I20+J20+K20+L20 -> 548.275 | N20: =(M20-L20)*9.45% -> 51.811988 | P20: 0 | R20: =+N20+O20+P20+Q20 -> 51.811988 | S20: =M20-R20 -> 496.46301
A21: 17 | B21: Valeria Cortez | C21: Obreros | D21: 45674 | E21: 482 | F21: 30 | G21: =(E21/30)*F21 -> 482 | H21: =((E21/160)*1.25)*0 -> 0 | I21: =((E21/160)*1.5)*4 -> 18.075 | J21: =((E21/160)*2)*8 -> 48.2 | L21: =(G21+H21+I21+J21+K21)/12*0 -> 0 | M21: =+G21+H21+I21+J21+K21+L21 -> 548.275 | N21: =(M21-L21)*9.45% -> 51.811988 | P21: 0 | R21: =+N21+O21+P21+Q21 -> 51.811988 | S21: =M21-R21 -> 496.46301
A22: 18 | B22: Giuliana Armas | C22: Obreros | D22: 45675 | E22: 482 | F22: 30 | G22: =(E22/30)*F22 -> 482 | H22: =((E22/160)*1.25)*0 -> 0 | I22: =((E22/160)*1.5)*4 -> 18.075 | J22: =((E22/160)*2)*8 -> 48.2 | L22: =(G22+H22+I22+J22+K22)/12*0 -> 0 | M22: =+G22+H22+I22+J22+K22+L22 -> 548.275 | N22: =(M22-L22)*9.45% -> 51.811988 | P22: 0 | R22: =+N22+O22+P22+Q22 -> 51.811988 | S22: =M22-R22 -> 496.46301
A23: 19 | B23: Valeria Cortez | C23: Obreros | D23: 45676 | E23: 482 | F23: 30 | G23: =(E23/30)*F23 -> 482 | H23: =((E23/160)*1.25)*0 -> 0 | I23: =((E23/160)*1.5)*4 -> 18.075 | J23: =((E23/160)*2)*8 -> 48.2 | L23: =(G23+H23+I23+J23+K23)/12*0 -> 0 | M23: =+G23+H23+I23+J23+K23+L23 -> 548.275 | N23: =(M23-L23)*9.45% -> 51.811988 | P23: 0 | R23: =+N23+O23+P23+Q23 -> 51.811988 | S23: =M23-R23 -> 496.46301
A24: 20 | B24: Giuliana Armas | C24: Obreros | D24: 45677 | E24: 482 | F24: 30 | G24: =(E24/30)*F24 -> 482 | H24: =((E24/160)*1.25)*0 -> 0 | I24: =((E24/160)*1.5)*4 -> 18.075 | J24: =((E24/160)*2)*8 -> 48.2 | L24: =(G24+H24+I24+J24+K24)/12*0 -> 0 | M24: =+G24+H24+I24+J24+K24+L24 -> 548.275 | N24: =(M24-L24)*9.45% -> 51.811988 | P24: 0 | R24: =+N24+O24+P24+Q24 -> 51.811988 | S24: =M24-R24 -> 496.46301
A25: 21 | B25: Valeria Cortez | C25: Obreros | D25: 45678 | E25: 482 | F25: 30 | G25: =(E25/30)*F25 -> 482 | H25: =((E25/160)*1.25)*0 -> 0 | I25: =((E25/160)*1.5)*4 -> 18.075 | J25: =((E25/160)*2)*8 -> 48.2 | L25: =(G25+H25+I25+J25+K25)/12*0 -> 0 | M25: =+G25+H25+I25+J25+K25+L25 -> 548.275 | N25: =(M25-L25)*9.45% -> 51.811988 | P25: 0 | R25: =+N25+O25+P25+Q25 -> 51.811988 | S25: =M25-R25 -> 496.46301
A26: 22 | B26: Giuliana Armas | C26: Obreros | D26: 45679 | E26: 482 | F26: 30 | G26: =(E26/30)*F26 -> 482 | H26: =((E26/160)*1.25)*0 -> 0 | I26: =((E26/160)*1.5)*4 -> 18.075 | J26: =((E26/160)*2)*8 -> 48.2 | L26: =(G26+H26+I26+J26+K26)/12*0 -> 0 | M26: =+G26+H26+I26+J26+K26+L26 -> 548.275 | N26: =(M26-L26)*9.45% -> 51.811988 | P26: 0 | R26: =+N26+O26+P26+Q26 -> 51.811988 | S26: =M26-R26 -> 496.46301
A27: 23 | B27: Valeria Cortez | C27: Obreros | D27: 45680 | E27: 482 | F27: 30 | G27: =(E27/30)*F27 -> 482 | H27: =((E27/160)*1.25)*0 -> 0 | I27: =((E27/160)*1.5)*4 -> 18.075 | J27: =((E27/160)*2)*8 -> 48.2 | L27: =(G27+H27+I27+J27+K27)/12*0 -> 0 | M27: =+G27+H27+I27+J27+K27+L27 -> 548.275 | N27: =(M27-L27)*9.45% -> 51.811988 | P27: 0 | R27: =+N27+O27+P27+Q27 -> 51.811988 | S27: =M27-R27 -> 496.46301
A28: 24 | B28: Giuliana Armas | C28: Obreros | D28: 45681 | E28: 482 | F28: 30 | G28: =(E28/30)*F28 -> 482 | H28: =((E28/160)*1.25)*0 -> 0 | I28: =((E28/160)*1.5)*4 -> 18.075 | J28: =((E28/160)*2)*8 -> 48.2 | L28: =(G28+H28+I28+J28+K28)/12*0 -> 0 | M28: =+G28+H28+I28+J28+K28+L28 -> 548.275 | N28: =(M28-L28)*9.45% -> 51.811988 | P28: 0 | R28: =+N28+O28+P28+Q28 -> 51.811988 | S28: =M28-R28 -> 496.46301
A29: 25 | B29: Valeria Cortez | C29: Obreros | D29: 45682 | E29: 482 | F29: 30 | G29: =(E29/30)*F29 -> 482 | H29: =((E29/160)*1.25)*0 -> 0 | I29: =((E29/160)*1.5)*4 -> 18.075 | J29: =((E29/160)*2)*8 -> 48.2 | L29: =(G29+H29+I29+J29+K29)/12*0 -> 0 | M29: =+G29+H29+I29+J29+K29+L29 -> 548.275 | N29: =(M29-L29)*9.45% -> 51.811988 | P29: 0 | R29: =+N29+O29+P29+Q29 -> 51.811988 | S29: =M29-R29 -> 496.46301
A30: 26 | B30: Giuliana Armas | C30: Obreros | D30: 45683 | E30: 482 | F30: 30 | G30: =(E30/30)*F30 -> 482 | H30: =((E30/160)*1.25)*0 -> 0 | I30: =((E30/160)*1.5)*4 -> 18.075 | J30: =((E30/160)*2)*8 -> 48.2 | L30: =(G30+H30+I30+J30+K30)/12*0 -> 0 | M30: =+G30+H30+I30+J30+K30+L30 -> 548.275 | N30: =(M30-L30)*9.45% -> 51.811988 | P30: 0 | R30: =+N30+O30+P30+Q30 -> 51.811988 | S30: =M30-R30 -> 496.46301
A31: 27 | B31: Valeria Cortez | C31: Obreros | D31: 45684 | E31: 482 | F31: 30 | G31: =(E31/30)*F31 -> 482 | H31: =((E31/160)*1.25)*0 -> 0 | I31: =((E31/160)*1.5)*4 -> 18.075 | J31: =((E31/160)*2)*8 -> 48.2 | L31: =(G31+H31+I31+J31+K31)/12*0 -> 0 | M31: =+G31+H31+I31+J31+K31+L31 -> 548.275 | N31: =(M31-L31)*9.45% -> 51.811988 | P31: 0 | R31: =+N31+O31+P31+Q31 -> 51.811988 | S31: =M31-R31 -> 496.46301
... A34: 30 | B34: Giuliana Armas | C34: Obreros | D34: 45687 | E34: 482 | F34: 30 | G34: =(E34/30)*F34 -> 482 | H34: =((E34/160)*1.25)*0 -> 0 | I34: =((E34/160)*1.5)*4 -> 18.075 | J34: =((E34/160)*2)*8 -> 48.2 | L34: =(G34+H34+I34+J34+K34)/12*0 -> 0 | M34: =+G34+H34+I34+J34+K34+L34 -> 548.275 | N34: =(M34-L34)*9.45% -> 51.811988 | P34: 0 | R34: =+N34+O34+P34+Q34 -> 51.811988 | S34: =M34-R34 -> 496.46301
E35: =SUM(E5:E34) -> 14460 | F35: =SUM(F5:F34) -> 900 | G35: =SUM(G5:G34) -> 14460 | H35: =SUM(H5:H34) -> 0 | I35: =SUM(I5:I34) -> 542.25 | J35: =SUM(J5:J34) -> 1446 | K35: =SUM(K5:K34) -> 0 | L35: =SUM(L5:L34) -> 685.34375 | ... S35: =SUM(S5:S34) -> 15579.234
B37: MANO DE OBRA INDIRECTA | H37: HORAS EXTRAS Y SUPLEMENTARIAS
A38: No. | B38: NOMBRES Y APELLIDOS | C38: CARGO | D38: FECHA INGRESO | E38: SUELDO | F38: DIAS TRABAJADOS | G38: SUELDO LIQUIDO | H38: 0.25 | I38: 0.5 | J38: 1 | K38: OTROS INGRESOS | L38: FONDO DE RESERVA | M38: TOTAL DE INGRESOS | N38: APORTE PERSONAL iess | O38: IMPUESTO RENTA | P38: RETENCIONES JUDICIALES | Q38: 0TROS DESCUENTOS | R38: TOTAL EGRESOS | S38: VALOR A RECIBIR
A39: 1 | B39: Alan Brito Delgado | C39: Jefe de Producción | D39: 45658 | E39: 700 | F39: 30 | G39: =(E39/30)*F39 -> 700 | H39: =((E39/160)*1.25)*0 -> 0 | I39: =((E39/160)*1.5)*4 -> 26.25 | J39: =((E39/160)*2)*8 -> 70 | K39: 100 | L39: =(G39+H39+I39+J39+K39)/12 -> 74.6875 | M39: =+G39+H39+I39+J39+K39+L39 -> 970.9375 | N39: =(M39-L39)*9.45% -> 84.695625 | P39: 0 | R39: =+N39+O39+P39+Q39 -> 84.695625 | S39: =M39-R39 -> 886.24188
A40: 2 | B40: Nori Navas Robles | C40: Supervisor | D40: 45659 | E40: 650 | F40: 30 | G40: =(E40/30)*F40 -> 650 | H40: =((E40/160)*1.25)*0 -> 0 | I40: =((E40/160)*1.5)*4 -> 24.375 | J40: =((E40/160)*2)*8 -> 65 | K40: 60 | L40: =(G40+H40+I40+J40+K40)/12 -> 66.614583 | M40: =+G40+H40+I40+J40+K40+L40 -> 865.98958 | N40: =(M40-L40)*9.45% -> 75.540937 | P40: 0 | R40: =+N40+O40+P40+Q40 -> 75.540937 | S40: =M40-R40 -> 790.44865
G41: =SUM(G39:G40) -> 1350 | H41: =SUM(H39:H40) -> 0 | I41: =SUM(I39:I40) -> 50.625 | J41: =SUM(J39:J40) -> 135 | K41: =SUM(K39:K40) -> 160 | L41: =SUM(L39:L40) -> 141.30208 | M41: =SUM(M39:M40) -> 1836.9271 | N41: =SUM(N39:N40) -> 160.23656 | ... S41: =SUM(S39:S40) -> 1676.6905
A42: ROL DE PROVISIONES
D43: Rol de proviciones
A46: No. | B46: NOMBRES Y APELLIDOS | C46: CARGO | D46: FECHA INGRESO | E46: TOTAL DE INGRESOS | F46: XIII SUELDO | G46: XIV SUELDO | H46: VACACIONES | I46: FONDO RESERVA | J46: APORTE PATRONAL | K46: TOTAL PROVISIONES
A47: 1 | B47: Alan Brito Delgado | C47: Obreros | D47: 45200 | E47: =M5-L5 -> 548.275 | F47: =E47/12 -> 45.689583 | G47: =482/12 -> 40.166667 | H47: =E47/24 -> 22.844792 | I47: 0 | J47: =E47*12.15% -> 66.615413 | K47: =SUM(F47:J47) -> 175.31645
A48: 2 | B48: Nori Navas Robles | C48: Obreros | D48: 45201 | E48: =M6-L6 -> 548.275 | F48: =E48/12 -> 45.689583 | G48: =482/12 -> 40.166667 | H48: =E48/24 -> 22.844792 | I48: 0 | J48: =E48*12.15% -> 66.615413 | K48: =SUM(F48:J48) -> 175.31645
...

Sheet Hoja2
